Workbook
Name MORANTE: '[1]DISPATCHED (VT11)'!#REF!
Name MORANTE: 'DISPATCHED (VT11)'!$F$248
Name T: 'DISPATCHED (VT11)'!$E$707

Sheet LO TEXT UPDATE
B1: Team Good Morning,
B2: New Paranaque Region Delivery Update as of
B3: ='DISPATCHED (VT11)'!C4 -> 46125
B4: 07:00H
B6: Current | C6: PLAN | D6: DISP | E6: VAR | F6: %
B7: KA | C7: ='Report Summary'!R8 -> 89 | D7: ='Report Summary'!S8 -> 57 | E7: =C7-D7 -> 32 | F7: =D7/C7 -> 0.64044944
C8: ='Report Summary'!R39 -> 25665 | D8: ='Report Summary'!S39 -> 14252
B9: HOD | C9: ='Report Summary'!R11 -> 11 | D9: ='Report Summary'!S11 -> 3 | E9: =C9-D9 -> 8 | F9: =D9/C9 -> 0.27272727
C10: ='Report Summary'!R42 -> 3504 | D10: ='Report Summary'!S42 -> 921
B11: DP | C11: ='Report Summary'!R14 -> 27 | D11: ='Report Summary'!S14 -> 6 | E11: =C11-D11 -> 21 | F11: =D11/C11 -> 0.22222222
C12: ='Report Summary'!R45 -> 7184 | D12: ='Report Summary'!S45 -> 1495
B13: LWS | C13: ='Report Summary'!R17 -> 8 | D13: ='Report Summary'!S17 -> 3 | E13: =C13-D13 -> 5 | F13: =D13/C13 -> 0.375
C14: ='Report Summary'!R48 -> 1900 | D14: ='Report Summary'!S48 -> 777
B15: WS | C15: ='Report Summary'!R20 -> 21 | D15: ='Report Summary'!S20 -> 11 | E15: =C15-D15 -> 10 | F15: =D15/C15 -> 0.52380952
C16: ='Report Summary'!R51 -> 5796 | D16: ='Report Summary'!S51 -> 3003
B17: XDOCK | C17: ='Report Summary'!R23 -> 0 | D17: ='Report Summary'!S23 -> 0 | E17: =C17-D17 -> 0 | F17: =D17/C17 -> #DIV/0!
C18: ='Report Summary'!R54 -> 0 | D18: ='Report Summary'!S54 -> 0
B19: PICK UP | C19: ='Report Summary'!R26 -> 30 | D19: ='Report Summary'!S26 -> 3 | E19: =C19-D19 -> 27 | F19: =D19/C19 -> 0.1
C20: ='Report Summary'!R57 -> 14750 | D20: ='Report Summary'!S57 -> 1288
B22: TOTAL CURRENT | C22: =C11+C7+C13+C15+C9+C17+C19 -> 186 | D22: =D11+D7+D13+D15+D9+D17+D19 -> 83 | E22: =C22-D22 -> 103 | F22: =D22/C22 -> 0.44623656
C23: =C12+C8+C14+C16+C10+C18+C20 -> 58799 | D23: =D12+D8+D14+D16+D10+D18+D20 -> 21736
B25: ADVANCE:
B26: KA | C26: ='Report Summary'!R10 -> #REF! | D26: ='Report Summary'!S10 -> 0 | E26: =C26-D26 -> #REF! | F26: =D26/C26 -> #REF!
C27: ='Report Summary'!R41 -> 0 | D27: ='Report Summary'!S41 -> 0
B28: HOD | C28: ='Report Summary'!R13 -> #REF! | D28: ='Report Summary'!S13 -> 0 | E28: =C28-D28 -> #REF! | F28: =D28/C28 -> #REF!
C29: ='Report Summary'!R44 -> 0 | D29: ='Report Summary'!S44 -> 0
B30: DP | C30: ='Report Summary'!R16 -> #REF! | D30: ='Report Summary'!S16 -> 0 | E30: =C30-D30 -> #REF! | F30: =D30/C30 -> #REF!
C31: ='Report Summary'!R47 -> 0 | D31: ='Report Summary'!S47 -> 0
B32: LWS | C32: ='Report Summary'!R19 -> #REF! | D32: ='Report Summary'!S19 -> 0 | E32: =C32-D32 -> #REF! | F32: =D32/C32 -> #REF!
C33: ='Report Summary'!R50 -> 0 | D33: ='Report Summary'!S50 -> 0
B34: WS | C34: ='Report Summary'!R22 -> #REF! | D34: ='Report Summary'!S22 -> 0 | E34: =C34-D34 -> #REF! | F34: =D34/C34 -> #REF!
C35: ='Report Summary'!R53 -> 0 | D35: ='Report Summary'!S53 -> 0
B36: XDOCK | C36: ='Report Summary'!R25 -> 0 | D36: ='Report Summary'!S25 -> 0 | E36: =C36-D36 -> 0 | F36: =D36/C36 -> #DIV/0!
C37: ='Report Summary'!R56 -> 0 | D37: ='Report Summary'!S56 -> 0
B38: PICK UP | C38: ='Report Summary'!R28 -> #REF! | D38: ='Report Summary'!S28 -> 0 | E38: =C38-D38 -> #REF! | F38: =D38/C38 -> #REF!
C39: ='Report Summary'!R59 -> 0 | D39: ='Report Summary'!S59 -> 0
B41: TOTAL ADVANCE | C41: =C30+C26+C32+C34+C28+C36+C38 -> #REF! | D41: =D30+D26+D32+D34+D28+D36+D38 -> 0 | E41: =C41-D41 -> #REF! | F41: =D41/C41 -> #REF!
C42: =C31+C27+C33+C35+C29+C37+C39 -> 0 | D42: =D31+D27+D33+D35+D29+D37+D39 -> 0
B44: BACKLOG:
B45: KA | C45: ='Report Summary'!R9 -> #REF! | D45: ='Report Summary'!S9 -> 0 | E45: =C45-D45 -> #REF! | F45: =D45/C45 -> #REF!
...

Sheet Summarized Plan
A1: SHIPMENT | B1: OUTLET NAME | C1: Qty | D1: No. of Drops | E1: CUBES | G1: CG | H1: DATE | I1: VENDOR | J1: TSM | K1: KA CLUSTER | L1: 14P | M1: =COUNTIF(#REF!,14) -> #REF! | O1: Duplicated? | P1: =IF(COUNTIF('DISPATCHED (VT11)'!$E:$E,'Summarized Plan'!A1)=0,"",COUNTIF('DISPATCHED (VT11)'!$E:$E,'Summarized Plan'!A1)) | Q1: =IF(A1="","",IF(ISNA(VLOOKUP(A1,'DISPATCHED (VT11)'!$E:$M,9,0)),"",VLOOKUP(A1,'DISPATCHED (VT11)'!$E:$M,9,0))) | R1: =IF(H1="","",IF(H1<#REF!,1,0)) -> #REF! | S1: =IF(H1="","",IF(H1>#REF!,1,0)) -> #REF! | T1: =IF(H1="","",IF(H1=#REF!,1,0)) -> #REF! | U1: =IF(I1="","",1) -> 1 | W1: =SUM(#REF!) -> #REF! | Z1: PLATE
A2: 30978993 | B2: CARRY ALL FOOD ENTERPRISES INC. | F2: PULLOUT EMPTIES | H2: 46114 | M2: =VLOOKUP(B2,REFERENCE!$A$2:D209,4,0) -> #N/A | N2: =VLOOKUP(B2,REFERENCE!A:C,3,FALSE) -> TAG-PUP | O2: =COUNTIF($A:$A,A2) -> 1 | P2: =IF(COUNTIF('DISPATCHED (VT11)'!$E:$E,'Summarized Plan'!A2)=0,"",COUNTIF('DISPATCHED (VT11)'!$E:$E,'Summarized Plan'!A2)) | Q2: =IF(A2="","",IF(ISNA(VLOOKUP(A2,'DISPATCHED (VT11)'!$E:$M,9,0)),"",VLOOKUP(A2,'DISPATCHED (VT11)'!$E:$M,9,0))) | R2: =IF(H2="","",IF(H2<#REF!,1,0)) -> #REF! | S2: =IF(H2="","",IF(H2>#REF!,1,0)) -> #REF! | T2: =IF(H2="","",IF(H2=#REF!,1,0)) -> #REF! | U2: =IF(I2="","",1)
A3: 30978994 | B3: CARRY ALL FOOD ENTERPRISES INC. | F3: PULLOUT EMPTIES | H3: 46114 | M3: =VLOOKUP(B3,REFERENCE!$A$2:D210,4,0) -> #N/A | N3: =VLOOKUP(B3,REFERENCE!A:C,3,FALSE) -> TAG-PUP | O3: =COUNTIF($A:$A,A3) -> 1 | P3: =IF(COUNTIF('DISPATCHED (VT11)'!$E:$E,'Summarized Plan'!A3)=0,"",COUNTIF('DISPATCHED (VT11)'!$E:$E,'Summarized Plan'!A3)) | Q3: =IF(A3="","",IF(ISNA(VLOOKUP(A3,'DISPATCHED (VT11)'!$E:$M,9,0)),"",VLOOKUP(A3,'DISPATCHED (VT11)'!$E:$M,9,0))) | R3: =IF(H3="","",IF(H3<#REF!,1,0)) -> #REF! | S3: =IF(H3="","",IF(H3>#REF!,1,0)) -> #REF! | T3: =IF(H3="","",IF(H3=#REF!,1,0)) -> #REF! | U3: =IF(I3="","",1)
A4: 30978995 | B4: CARRY ALL FOOD ENTERPRISES INC. | F4: PULLOUT EMPTIES | H4: 46114 | M4: =VLOOKUP(B4,REFERENCE!$A$2:D211,4,0) -> #N/A | N4: =VLOOKUP(B4,REFERENCE!A:C,3,FALSE) -> TAG-PUP | O4: =COUNTIF($A:$A,A4) -> 1 | P4: =IF(COUNTIF('DISPATCHED (VT11)'!$E:$E,'Summarized Plan'!A4)=0,"",COUNTIF('DISPATCHED (VT11)'!$E:$E,'Summarized Plan'!A4)) | Q4: =IF(A4="","",IF(ISNA(VLOOKUP(A4,'DISPATCHED (VT11)'!$E:$M,9,0)),"",VLOOKUP(A4,'DISPATCHED (VT11)'!$E:$M,9,0))) | R4: =IF(H4="","",IF(H4<#REF!,1,0)) -> #REF! | S4: =IF(H4="","",IF(H4>#REF!,1,0)) -> #REF! | T4: =IF(H4="","",IF(H4=#REF!,1,0)) -> #REF! | U4: =IF(I4="","",1)
A5: 30978996 | B5: CARRY ALL FOOD ENTERPRISES INC. | F5: PULLOUT EMPTIES | H5: 46114 | M5: =VLOOKUP(B5,REFERENCE!$A$2:D212,4,0) -> #N/A | N5: =VLOOKUP(B5,REFERENCE!A:C,3,FALSE) -> TAG-PUP | O5: =COUNTIF($A:$A,A5) -> 1 | P5: =IF(COUNTIF('DISPATCHED (VT11)'!$E:$E,'Summarized Plan'!A5)=0,"",COUNTIF('DISPATCHED (VT11)'!$E:$E,'Summarized Plan'!A5)) | Q5: =IF(A5="","",IF(ISNA(VLOOKUP(A5,'DISPATCHED (VT11)'!$E:$M,9,0)),"",VLOOKUP(A5,'DISPATCHED (VT11)'!$E:$M,9,0))) | R5: =IF(H5="","",IF(H5<#REF!,1,0)) -> #REF! | S5: =IF(H5="","",IF(H5>#REF!,1,0)) -> #REF! | T5: =IF(H5="","",IF(H5=#REF!,1,0)) -> #REF! | U5: =IF(I5="","",1)
A6: 30978997 | B6: CARRY ALL FOOD ENTERPRISES INC. | F6: PULLOUT EMPTIES | H6: 46114 | M6: =VLOOKUP(B6,REFERENCE!$A$2:D213,4,0) -> #N/A | N6: =VLOOKUP(B6,REFERENCE!A:C,3,FALSE) -> TAG-PUP | O6: =COUNTIF($A:$A,A6) -> 1 | P6: =IF(COUNTIF('DISPATCHED (VT11)'!$E:$E,'Summarized Plan'!A6)=0,"",COUNTIF('DISPATCHED (VT11)'!$E:$E,'Summarized Plan'!A6)) | Q6: =IF(A6="","",IF(ISNA(VLOOKUP(A6,'DISPATCHED (VT11)'!$E:$M,9,0)),"",VLOOKUP(A6,'DISPATCHED (VT11)'!$E:$M,9,0))) | R6: =IF(H6="","",IF(H6<#REF!,1,0)) -> #REF! | S6: =IF(H6="","",IF(H6>#REF!,1,0)) -> #REF! | T6: =IF(H6="","",IF(H6=#REF!,1,0)) -> #REF! | U6: =IF(I6="","",1)
A7: 30978998 | B7: CARRY ALL FOOD ENTERPRISES INC. | F7: PULLOUT EMPTIES | H7: 46114 | M7: =VLOOKUP(B7,REFERENCE!$A$2:D214,4,0) -> #N/A | N7: =VLOOKUP(B7,REFERENCE!A:C,3,FALSE) -> TAG-PUP | O7: =COUNTIF($A:$A,A7) -> 1 | P7: =IF(COUNTIF('DISPATCHED (VT11)'!$E:$E,'Summarized Plan'!A7)=0,"",COUNTIF('DISPATCHED (VT11)'!$E:$E,'Summarized Plan'!A7)) | Q7: =IF(A7="","",IF(ISNA(VLOOKUP(A7,'DISPATCHED (VT11)'!$E:$M,9,0)),"",VLOOKUP(A7,'DISPATCHED (VT11)'!$E:$M,9,0))) | R7: =IF(H7="","",IF(H7<#REF!,1,0)) -> #REF! | S7: =IF(H7="","",IF(H7>#REF!,1,0)) -> #REF! | T7: =IF(H7="","",IF(H7=#REF!,1,0)) -> #REF! | U7: =IF(I7="","",1)
A8: 30978999 | B8: CARRY ALL FOOD ENTERPRISES INC. | F8: PULLOUT EMPTIES | H8: 46114 | M8: =VLOOKUP(B8,REFERENCE!$A$2:D215,4,0) -> #N/A | N8: =VLOOKUP(B8,REFERENCE!A:C,3,FALSE) -> TAG-PUP | O8: =COUNTIF($A:$A,A8) -> 1 | P8: =IF(COUNTIF('DISPATCHED (VT11)'!$E:$E,'Summarized Plan'!A8)=0,"",COUNTIF('DISPATCHED (VT11)'!$E:$E,'Summarized Plan'!A8)) | Q8: =IF(A8="","",IF(ISNA(VLOOKUP(A8,'DISPATCHED (VT11)'!$E:$M,9,0)),"",VLOOKUP(A8,'DISPATCHED (VT11)'!$E:$M,9,0))) | R8: =IF(H8="","",IF(H8<#REF!,1,0)) -> #REF! | S8: =IF(H8="","",IF(H8>#REF!,1,0)) -> #REF! | T8: =IF(H8="","",IF(H8=#REF!,1,0)) -> #REF! | U8: =IF(I8="","",1)
A9: 30979020 | B9: CARRY ALL FOOD ENTERPRISES INC. | F9: PULLOUT EMPTIES | H9: 46114 | M9: =VLOOKUP(B9,REFERENCE!$A$2:D216,4,0) -> #N/A | N9: =VLOOKUP(B9,REFERENCE!A:C,3,FALSE) -> TAG-PUP | O9: =COUNTIF($A:$A,A9) -> 1 | P9: =IF(COUNTIF('DISPATCHED (VT11)'!$E:$E,'Summarized Plan'!A9)=0,"",COUNTIF('DISPATCHED (VT11)'!$E:$E,'Summarized Plan'!A9)) | Q9: =IF(A9="","",IF(ISNA(VLOOKUP(A9,'DISPATCHED (VT11)'!$E:$M,9,0)),"",VLOOKUP(A9,'DISPATCHED (VT11)'!$E:$M,9,0))) | R9: =IF(H9="","",IF(H9<#REF!,1,0)) -> #REF! | S9: =IF(H9="","",IF(H9>#REF!,1,0)) -> #REF! | T9: =IF(H9="","",IF(H9=#REF!,1,0)) -> #REF! | U9: =IF(I9="","",1)
A10: 30979021 | B10: CARRY ALL FOOD ENTERPRISES INC. | F10: PULLOUT EMPTIES | H10: 46114 | M10: =VLOOKUP(B10,REFERENCE!$A$2:D217,4,0) -> #N/A | N10: =VLOOKUP(B10,REFERENCE!A:C,3,FALSE) -> TAG-PUP | O10: =COUNTIF($A:$A,A10) -> 1 | P10: =IF(COUNTIF('DISPATCHED (VT11)'!$E:$E,'Summarized Plan'!A10)=0,"",COUNTIF('DISPATCHED (VT11)'!$E:$E,'Summarized Plan'!A10)) | Q10: =IF(A10="","",IF(ISNA(VLOOKUP(A10,'DISPATCHED (VT11)'!$E:$M,9,0)),"",VLOOKUP(A10,'DISPATCHED (VT11)'!$E:$M,9,0))) | R10: =IF(H10="","",IF(H10<#REF!,1,0)) -> #REF! | S10: =IF(H10="","",IF(H10>#REF!,1,0)) -> #REF! | T10: =IF(H10="","",IF(H10=#REF!,1,0)) -> #REF! | U10: =IF(I10="","",1)
A11: 30979022 | B11: CARRY ALL FOOD ENTERPRISES INC. | F11: PULLOUT EMPTIES | H11: 46114 | M11: =VLOOKUP(B11,REFERENCE!$A$2:D218,4,0) -> #N/A | N11: =VLOOKUP(B11,REFERENCE!A:C,3,FALSE) -> TAG-PUP | O11: =COUNTIF($A:$A,A11) -> 1 | P11: =IF(COUNTIF('DISPATCHED (VT11)'!$E:$E,'Summarized Plan'!A11)=0,"",COUNTIF('DISPATCHED (VT11)'!$E:$E,'Summarized Plan'!A11)) | Q11: =IF(A11="","",IF(ISNA(VLOOKUP(A11,'DISPATCHED (VT11)'!$E:$M,9,0)),"",VLOOKUP(A11,'DISPATCHED (VT11)'!$E:$M,9,0))) | R11: =IF(H11="","",IF(H11<#REF!,1,0)) -> #REF! | S11: =IF(H11="","",IF(H11>#REF!,1,0)) -> #REF! | T11: =IF(H11="","",IF(H11=#REF!,1,0)) -> #REF! | U11: =IF(I11="","",1)
A12: 30979023 | B12: CARRY ALL FOOD ENTERPRISES INC. | F12: PULLOUT EMPTIES | H12: 46114 | M12: =VLOOKUP(B12,REFERENCE!$A$2:D219,4,0) -> #N/A | N12: =VLOOKUP(B12,REFERENCE!A:C,3,FALSE) -> TAG-PUP | O12: =COUNTIF($A:$A,A12) -> 1 | P12: =IF(COUNTIF('DISPATCHED (VT11)'!$E:$E,'Summarized Plan'!A12)=0,"",COUNTIF('DISPATCHED (VT11)'!$E:$E,'Summarized Plan'!A12)) | Q12: =IF(A12="","",IF(ISNA(VLOOKUP(A12,'DISPATCHED (VT11)'!$E:$M,9,0)),"",VLOOKUP(A12,'DISPATCHED (VT11)'!$E:$M,9,0))) | R12: =IF(H12="","",IF(H12<#REF!,1,0)) -> #REF! | S12: =IF(H12="","",IF(H12>#REF!,1,0)) -> #REF! | T12: =IF(H12="","",IF(H12=#REF!,1,0)) -> #REF! | U12: =IF(I12="","",1)
A13: 30979024 | B13: CARRY ALL FOOD ENTERPRISES INC. | F13: PULLOUT EMPTIES | H13: 46114 | M13: =VLOOKUP(B13,REFERENCE!$A$2:D220,4,0) -> #N/A | N13: =VLOOKUP(B13,REFERENCE!A:C,3,FALSE) -> TAG-PUP | O13: =COUNTIF($A:$A,A13) -> 1 | P13: =IF(COUNTIF('DISPATCHED (VT11)'!$E:$E,'Summarized Plan'!A13)=0,"",COUNTIF('DISPATCHED (VT11)'!$E:$E,'Summarized Plan'!A13)) | Q13: =IF(A13="","",IF(ISNA(VLOOKUP(A13,'DISPATCHED (VT11)'!$E:$M,9,0)),"",VLOOKUP(A13,'DISPATCHED (VT11)'!$E:$M,9,0))) | R13: =IF(H13="","",IF(H13<#REF!,1,0)) -> #REF! | S13: =IF(H13="","",IF(H13>#REF!,1,0)) -> #REF! | T13: =IF(H13="","",IF(H13=#REF!,1,0)) -> #REF! | U13: =IF(I13="","",1)
... A60: 31002652 | B60: EBON GEN MDSE | F60: PULLOUT EMPTIES | H60: 46120 | M60: =VLOOKUP(B60,REFERENCE!$A$2:D267,4,0) -> ANDRE GORDONCILLO | N60: =VLOOKUP(B60,REFERENCE!A:C,3,FALSE) -> LP-LWS | O60: =COUNTIF($A:$A,A60) -> 1 | P60: =IF(COUNTIF('DISPATCHED (VT11)'!$E:$E,'Summarized Plan'!A60)=0,"",COUNTIF('DISPATCHED (VT11)'!$E:$E,'Summarized Plan'!A60)) | Q60: =IF(A60="","",IF(ISNA(VLOOKUP(A60,'DISPATCHED (VT11)'!$E:$M,9,0)),"",VLOOKUP(A60,'DISPATCHED (VT11)'!$E:$M,9,0))) | R60: =IF(H60="","",IF(H60<#REF!,1,0)) -> #REF! | S60: =IF(H60="","",IF(H60>#REF!,1,0)) -> #REF! | T60: =IF(H60="","",IF(H60=#REF!,1,0)) -> #REF! | U60: =IF(I60="","",1)
A61: 31002724 | B61: PRINCESS DANAE MARKETING | F61: PULLOUT EMPTIES | H61: 46120 | M61: =VLOOKUP(B61,REFERENCE!$A$2:D269,4,0) -> ANDRE GORDONCILLO | N61: =VLOOKUP(B61,REFERENCE!A:C,3,FALSE) -> LP-WS | O61: =COUNTIF($A:$A,A61) -> 1 | P61: =IF(COUNTIF('DISPATCHED (VT11)'!$E:$E,'Summarized Plan'!A61)=0,"",COUNTIF('DISPATCHED (VT11)'!$E:$E,'Summarized Plan'!A61)) | Q61: =IF(A61="","",IF(ISNA(VLOOKUP(A61,'DISPATCHED (VT11)'!$E:$M,9,0)),"",VLOOKUP(A61,'DISPATCHED (VT11)'!$E:$M,9,0))) | R61: =IF(H61="","",IF(H61<#REF!,1,0)) -> #REF! | S61: =IF(H61="","",IF(H61>#REF!,1,0)) -> #REF! | T61: =IF(H61="","",IF(H61=#REF!,1,0)) -> #REF! | U61: =IF(I61="","",1)
A62: 31002725 | B62: PRINCESS DANAE MARKETING | F62: PULLOUT EMPTIES | H62: 46120 | M62: =VLOOKUP(B62,REFERENCE!$A$2:D270,4,0) -> ANDRE GORDONCILLO | N62: =VLOOKUP(B62,REFERENCE!A:C,3,FALSE) -> LP-WS | O62: =COUNTIF($A:$A,A62) -> 1 | P62: =IF(COUNTIF('DISPATCHED (VT11)'!$E:$E,'Summarized Plan'!A62)=0,"",COUNTIF('DISPATCHED (VT11)'!$E:$E,'Summarized Plan'!A62)) | Q62: =IF(A62="","",IF(ISNA(VLOOKUP(A62,'DISPATCHED (VT11)'!$E:$M,9,0)),"",VLOOKUP(A62,'DISPATCHED (VT11)'!$E:$M,9,0))) | R62: =IF(H62="","",IF(H62<#REF!,1,0)) -> #REF! | S62: =IF(H62="","",IF(H62>#REF!,1,0)) -> #REF! | T62: =IF(H62="","",IF(H62=#REF!,1,0)) -> #REF! | U62: =IF(I62="","",1)
A63: 31002726 | B63: PRINCESS DANAE MARKETING | F63: PULLOUT EMPTIES | H63: 46120 | M63: =VLOOKUP(B63,REFERENCE!$A$2:D271,4,0) -> ANDRE GORDONCILLO | N63: =VLOOKUP(B63,REFERENCE!A:C,3,FALSE) -> LP-WS | O63: =COUNTIF($A:$A,A63) -> 1 | P63: =IF(COUNTIF('DISPATCHED (VT11)'!$E:$E,'Summarized Plan'!A63)=0,"",COUNTIF('DISPATCHED (VT11)'!$E:$E,'Summarized Plan'!A63)) | Q63: =IF(A63="","",IF(ISNA(VLOOKUP(A63,'DISPATCHED (VT11)'!$E:$M,9,0)),"",VLOOKUP(A63,'DISPATCHED (VT11)'!$E:$M,9,0))) | R63: =IF(H63="","",IF(H63<#REF!,1,0)) -> #REF! | S63: =IF(H63="","",IF(H63>#REF!,1,0)) -> #REF! | T63: =IF(H63="","",IF(H63=#REF!,1,0)) -> #REF! | U63: =IF(I63="","",1)
A64: 31002732 | B64: RICAFORTZ CONSUMER GOODS TRADING | F64: BASBAS | H64: 46120 | M64: =VLOOKUP(B64,REFERENCE!$A$2:D273,4,0) -> #N/A | N64: =VLOOKUP(B64,REFERENCE!A:C,3,FALSE) -> #N/A | O64: =COUNTIF($A:$A,A64) -> 1 | P64: =IF(COUNTIF('DISPATCHED (VT11)'!$E:$E,'Summarized Plan'!A64)=0,"",COUNTIF('DISPATCHED (VT11)'!$E:$E,'Summarized Plan'!A64)) | Q64: =IF(A64="","",IF(ISNA(VLOOKUP(A64,'DISPATCHED (VT11)'!$E:$M,9,0)),"",VLOOKUP(A64,'DISPATCHED (VT11)'!$E:$M,9,0))) | R64: =IF(H64="","",IF(H64<#REF!,1,0)) -> #REF! | S64: =IF(H64="","",IF(H64>#REF!,1,0)) -> #REF! | T64: =IF(H64="","",IF(H64=#REF!,1,0)) -> #REF! | U64: =IF(I64="","",1)
A65: 31002733 | B65: RICAFORTZ CONSUMER GOODS TRADING | F65: PULLOUT EMPTIES | H65: 46120 | M65: =VLOOKUP(B65,REFERENCE!$A$2:D274,4,0) -> #N/A | N65: =VLOOKUP(B65,REFERENCE!A:C,3,FALSE) -> #N/A | O65: =COUNTIF($A:$A,A65) -> 1 | P65: =IF(COUNTIF('DISPATCHED (VT11)'!$E:$E,'Summarized Plan'!A65)=0,"",COUNTIF('DISPATCHED (VT11)'!$E:$E,'Summarized Plan'!A65)) | Q65: =IF(A65="","",IF(ISNA(VLOOKUP(A65,'DISPATCHED (VT11)'!$E:$M,9,0)),"",VLOOKUP(A65,'DISPATCHED (VT11)'!$E:$M,9,0))) | R65: =IF(H65="","",IF(H65<#REF!,1,0)) -> #REF! | S65: =IF(H65="","",IF(H65>#REF!,1,0)) -> #REF! | T65: =IF(H65="","",IF(H65=#REF!,1,0)) -> #REF! | U65: =IF(I65="","",1)
A66: 31002734 | B66: RICAFORTZ CONSUMER GOODS TRADING | F66: PULLOUT EMPTIES | H66: 46120 | M66: =VLOOKUP(B66,REFERENCE!$A$2:D275,4,0) -> #N/A | N66: =VLOOKUP(B66,REFERENCE!A:C,3,FALSE) -> #N/A | O66: =COUNTIF($A:$A,A66) -> 1 | P66: =IF(COUNTIF('DISPATCHED (VT11)'!$E:$E,'Summarized Plan'!A66)=0,"",COUNTIF('DISPATCHED (VT11)'!$E:$E,'Summarized Plan'!A66)) | Q66: =IF(A66="","",IF(ISNA(VLOOKUP(A66,'DISPATCHED (VT11)'!$E:$M,9,0)),"",VLOOKUP(A66,'DISPATCHED (VT11)'!$E:$M,9,0))) | R66: =IF(H66="","",IF(H66<#REF!,1,0)) -> #REF! | S66: =IF(H66="","",IF(H66>#REF!,1,0)) -> #REF! | T66: =IF(H66="","",IF(H66=#REF!,1,0)) -> #REF! | U66: =IF(I66="","",1)
A67: 31002735 | B67: RICAFORTZ CONSUMER GOODS TRADING | F67: PULLOUT EMPTIES | H67: 46120 | M67: =VLOOKUP(B67,REFERENCE!$A$2:D276,4,0) -> #N/A | N67: =VLOOKUP(B67,REFERENCE!A:C,3,FALSE) -> #N/A | O67: =COUNTIF($A:$A,A67) -> 1 | P67: =IF(COUNTIF('DISPATCHED (VT11)'!$E:$E,'Summarized Plan'!A67)=0,"",COUNTIF('DISPATCHED (VT11)'!$E:$E,'Summarized Plan'!A67)) | Q67: =IF(A67="","",IF(ISNA(VLOOKUP(A67,'DISPATCHED (VT11)'!$E:$M,9,0)),"",VLOOKUP(A67,'DISPATCHED (VT11)'!$E:$M,9,0))) | R67: =IF(H67="","",IF(H67<#REF!,1,0)) -> #REF! | S67: =IF(H67="","",IF(H67>#REF!,1,0)) -> #REF! | T67: =IF(H67="","",IF(H67=#REF!,1,0)) -> #REF! | U67: =IF(I67="","",1)
A68: 31002736 | B68: RICAFORTZ CONSUMER GOODS TRADING | F68: PULLOUT EMPTIES | H68: 46120 | M68: =VLOOKUP(B68,REFERENCE!$A$2:D277,4,0) -> #N/A | N68: =VLOOKUP(B68,REFERENCE!A:C,3,FALSE) -> #N/A | O68: =COUNTIF($A:$A,A68) -> 1 | P68: =IF(COUNTIF('DISPATCHED (VT11)'!$E:$E,'Summarized Plan'!A68)=0,"",COUNTIF('DISPATCHED (VT11)'!$E:$E,'Summarized Plan'!A68)) | Q68: =IF(A68="","",IF(ISNA(VLOOKUP(A68,'DISPATCHED (VT11)'!$E:$M,9,0)),"",VLOOKUP(A68,'DISPATCHED (VT11)'!$E:$M,9,0))) | R68: =IF(H68="","",IF(H68<#REF!,1,0)) -> #REF! | S68: =IF(H68="","",IF(H68>#REF!,1,0)) -> #REF! | T68: =IF(H68="","",IF(H68=#REF!,1,0)) -> #REF! | U68: =IF(I68="","",1)
A69: 31002737 | B69: RICAFORTZ CONSUMER GOODS TRADING | F69: PULLOUT EMPTIES | H69: 46120 | M69: =VLOOKUP(B69,REFERENCE!$A$2:D278,4,0) -> #N/A | N69: =VLOOKUP(B69,REFERENCE!A:C,3,FALSE) -> #N/A | O69: =COUNTIF($A:$A,A69) -> 1 | P69: =IF(COUNTIF('DISPATCHED (VT11)'!$E:$E,'Summarized Plan'!A69)=0,"",COUNTIF('DISPATCHED (VT11)'!$E:$E,'Summarized Plan'!A69)) | Q69: =IF(A69="","",IF(ISNA(VLOOKUP(A69,'DISPATCHED (VT11)'!$E:$M,9,0)),"",VLOOKUP(A69,'DISPATCHED (VT11)'!$E:$M,9,0))) | R69: =IF(H69="","",IF(H69<#REF!,1,0)) -> #REF! | S69: =IF(H69="","",IF(H69>#REF!,1,0)) -> #REF! | T69: =IF(H69="","",IF(H69=#REF!,1,0)) -> #REF! | U69: =IF(I69="","",1)
A70: 31002738 | B70: RICAFORTZ CONSUMER GOODS TRADING | F70: PULLOUT EMPTIES | H70: 46120 | M70: =VLOOKUP(B70,REFERENCE!$A$2:D279,4,0) -> #N/A | N70: =VLOOKUP(B70,REFERENCE!A:C,3,FALSE) -> #N/A | O70: =COUNTIF($A:$A,A70) -> 1 | P70: =IF(COUNTIF('DISPATCHED (VT11)'!$E:$E,'Summarized Plan'!A70)=0,"",COUNTIF('DISPATCHED (VT11)'!$E:$E,'Summarized Plan'!A70)) | Q70: =IF(A70="","",IF(ISNA(VLOOKUP(A70,'DISPATCHED (VT11)'!$E:$M,9,0)),"",VLOOKUP(A70,'DISPATCHED (VT11)'!$E:$M,9,0))) | R70: =IF(H70="","",IF(H70<#REF!,1,0)) -> #REF! | S70: =IF(H70="","",IF(H70>#REF!,1,0)) -> #REF! | T70: =IF(H70="","",IF(H70=#REF!,1,0)) -> #REF! | U70: =IF(I70="","",1)
A71: 31002739 | B71: RICAFORTZ CONSUMER GOODS TRADING | F71: PULLOUT EMPTIES | H71: 46120 | M71: =VLOOKUP(B71,REFERENCE!$A$2:D280,4,0) -> #N/A | N71: =VLOOKUP(B71,REFERENCE!A:C,3,FALSE) -> #N/A | O71: =COUNTIF($A:$A,A71) -> 1 | P71: =IF(COUNTIF('DISPATCHED (VT11)'!$E:$E,'Summarized Plan'!A71)=0,"",COUNTIF('DISPATCHED (VT11)'!$E:$E,'Summarized Plan'!A71)) | Q71: =IF(A71="","",IF(ISNA(VLOOKUP(A71,'DISPATCHED (VT11)'!$E:$M,9,0)),"",VLOOKUP(A71,'DISPATCHED (VT11)'!$E:$M,9,0))) | R71: =IF(H71="","",IF(H71<#REF!,1,0)) -> #REF! | S71: =IF(H71="","",IF(H71>#REF!,1,0)) -> #REF! | T71: =IF(H71="","",IF(H71=#REF!,1,0)) -> #REF! | U71: =IF(I71="","",1)
A72: 31002750 | B72: RICAFORTZ CONSUMER GOODS TRADING | F72: PULLOUT EMPTIES | H72: 46120 | M72: =VLOOKUP(B72,REFERENCE!$A$2:D281,4,0) -> #N/A | N72: =VLOOKUP(B72,REFERENCE!A:C,3,FALSE) -> #N/A | O72: =COUNTIF($A:$A,A72) -> 1 | P72: =IF(COUNTIF('DISPATCHED (VT11)'!$E:$E,'Summarized Plan'!A72)=0,"",COUNTIF('DISPATCHED (VT11)'!$E:$E,'Summarized Plan'!A72)) | Q72: =IF(A72="","",IF(ISNA(VLOOKUP(A72,'DISPATCHED (VT11)'!$E:$M,9,0)),"",VLOOKUP(A72,'DISPATCHED (VT11)'!$E:$M,9,0))) | R72: =IF(H72="","",IF(H72<#REF!,1,0)) -> #REF! | S72: =IF(H72="","",IF(H72>#REF!,1,0)) -> #REF! | T72: =IF(H72="","",IF(H72=#REF!,1,0)) -> #REF! | U72: =IF(I72="","",1)
A73: 31002751 | B73: RICAFORTZ CONSUMER GOODS TRADING | F73: PULLOUT EMPTIES | H73: 46120 | M73: =VLOOKUP(B73,REFERENCE!$A$2:D282,4,0) -> #N/A | N73: =VLOOKUP(B73,REFERENCE!A:C,3,FALSE) -> #N/A | O73: =COUNTIF($A:$A,A73) -> 1 | P73: =IF(COUNTIF('DISPATCHED (VT11)'!$E:$E,'Summarized Plan'!A73)=0,"",COUNTIF('DISPATCHED (VT11)'!$E:$E,'Summarized Plan'!A73)) | Q73: =IF(A73="","",IF(ISNA(VLOOKUP(A73,'DISPATCHED (VT11)'!$E:$M,9,0)),"",VLOOKUP(A73,'DISPATCHED (VT11)'!$E:$M,9,0))) | R73: =IF(H73="","",IF(H73<#REF!,1,0)) -> #REF! | S73: =IF(H73="","",IF(H73>#REF!,1,0)) -> #REF! | T73: =IF(H73="","",IF(H73=#REF!,1,0)) -> #REF! | U73: =IF(I73="","",1)
A74: 31002752 | B74: RICAFORTZ CONSUMER GOODS TRADING | F74: PULLOUT EMPTIES | H74: 46120 | M74: =VLOOKUP(B74,REFERENCE!$A$2:D283,4,0) -> #N/A | N74: =VLOOKUP(B74,REFERENCE!A:C,3,FALSE) -> #N/A | O74: =COUNTIF($A:$A,A74) -> 1 | P74: =IF(COUNTIF('DISPATCHED (VT11)'!$E:$E,'Summarized Plan'!A74)=0,"",COUNTIF('DISPATCHED (VT11)'!$E:$E,'Summarized Plan'!A74)) | Q74: =IF(A74="","",IF(ISNA(VLOOKUP(A74,'DISPATCHED (VT11)'!$E:$M,9,0)),"",VLOOKUP(A74,'DISPATCHED (VT11)'!$E:$M,9,0))) | R74: =IF(H74="","",IF(H74<#REF!,1,0)) -> #REF! | S74: =IF(H74="","",IF(H74>#REF!,1,0)) -> #REF! | T74: =IF(H74="","",IF(H74=#REF!,1,0)) -> #REF! | U74: =IF(I74="","",1)
A75: 31002753 | B75: RICAFORTZ CONSUMER GOODS TRADING | F75: PULLOUT EMPTIES | H75: 46120 | M75: =VLOOKUP(B75,REFERENCE!$A$2:D284,4,0) -> #N/A | N75: =VLOOKUP(B75,REFERENCE!A:C,3,FALSE) -> #N/A | O75: =COUNTIF($A:$A,A75) -> 1 | P75: =IF(COUNTIF('DISPATCHED (VT11)'!$E:$E,'Summarized Plan'!A75)=0,"",COUNTIF('DISPATCHED (VT11)'!$E:$E,'Summarized Plan'!A75)) | Q75: =IF(A75="","",IF(ISNA(VLOOKUP(A75,'DISPATCHED (VT11)'!$E:$M,9,0)),"",VLOOKUP(A75,'DISPATCHED (VT11)'!$E:$M,9,0))) | R75: =IF(H75="","",IF(H75<#REF!,1,0)) -> #REF! | S75: =IF(H75="","",IF(H75>#REF!,1,0)) -> #REF! | T75: =IF(H75="","",IF(H75=#REF!,1,0)) -> #REF! | U75: =IF(I75="","",1)
... A89: 31021829 | B89: GRACE AND BETCHAY GROCERY PRODUCTS | F89: PULLOUT EMPTIES | H89: 46123 | M89: =VLOOKUP(B89,REFERENCE!$A$2:D298,4,0) -> FERDINAND ALVAREZ | N89: =VLOOKUP(B89,REFERENCE!A:C,3,FALSE) -> TAG-LWS | O89: =COUNTIF($A:$A,A89) -> 1 | P89: =IF(COUNTIF('DISPATCHED (VT11)'!$E:$E,'Summarized Plan'!A89)=0,"",COUNTIF('DISPATCHED (VT11)'!$E:$E,'Summarized Plan'!A89)) | Q89: =IF(A89="","",IF(ISNA(VLOOKUP(A89,'DISPATCHED (VT11)'!$E:$M,9,0)),"",VLOOKUP(A89,'DISPATCHED (VT11)'!$E:$M,9,0))) | R89: =IF(H89="","",IF(H89<#REF!,1,0)) -> #REF! | S89: =IF(H89="","",IF(H89>#REF!,1,0)) -> #REF! | T89: =IF(H89="","",IF(H89=#REF!,1,0)) -> #REF! | U89: =IF(I89="","",1)
A90: 31015462 | B90: RETCHY STORE | C90: 240 | E90: 8 | G90: TAG-PUP | H90: 46122 | M90: =VLOOKUP(B90,REFERENCE!$A$2:D301,4,0) -> FERDINAND ALVAREZ | N90: =VLOOKUP(B90,REFERENCE!A:C,3,FALSE) -> TAG-PUP | O90: =COUNTIF($A:$A,A90) -> 1 | P90: =IF(COUNTIF('DISPATCHED (VT11)'!$E:$E,'Summarized Plan'!A90)=0,"",COUNTIF('DISPATCHED (VT11)'!$E:$E,'Summarized Plan'!A90)) | Q90: =IF(A90="","",IF(ISNA(VLOOKUP(A90,'DISPATCHED (VT11)'!$E:$M,9,0)),"",VLOOKUP(A90,'DISPATCHED (VT11)'!$E:$M,9,0))) | R90: =IF(H90="","",IF(H90<#REF!,1,0)) -> #REF! | S90: =IF(H90="","",IF(H90>#REF!,1,0)) -> #REF! | T90: =IF(H90="","",IF(H90=#REF!,1,0)) -> #REF! | U90: =IF(I90="","",1)
A91: 31015463 | B91: RVD MERCHANDISING BEVERAGE WHOLESAL | C91: 446 | E91: 14 | G91: LP-PUP | H91: 46122 | M91: =VLOOKUP(B91,REFERENCE!$A$2:D302,4,0) -> ANDRE GORDONCILLO | N91: =VLOOKUP(B91,REFERENCE!A:C,3,FALSE) -> LP-PUP | O91: =COUNTIF($A:$A,A91) -> 1 | P91: =IF(COUNTIF('DISPATCHED (VT11)'!$E:$E,'Summarized Plan'!A91)=0,"",COUNTIF('DISPATCHED (VT11)'!$E:$E,'Summarized Plan'!A91)) -> 1 | Q91: =IF(A91="","",IF(ISNA(VLOOKUP(A91,'DISPATCHED (VT11)'!$E:$M,9,0)),"",VLOOKUP(A91,'DISPATCHED (VT11)'!$E:$M,9,0))) -> 446 | R91: =IF(H91="","",IF(H91<#REF!,1,0)) -> #REF! | S91: =IF(H91="","",IF(H91>#REF!,1,0)) -> #REF! | T91: =IF(H91="","",IF(H91=#REF!,1,0)) -> #REF! | U91: =IF(I91="","",1)
A92: 30860399 | B92: CCBPI_PARAÑAQUE DC | C92: 8 | D92: 1 | E92: 0.04 | H92: 46093 | I92: PICKUP | M92: =VLOOKUP(B92,REFERENCE!$A$2:D305,4,0) -> #N/A | N92: =VLOOKUP(B92,REFERENCE!A:C,3,FALSE) -> #N/A | O92: =COUNTIF($A:$A,A92) -> 1 | P92: =IF(COUNTIF('DISPATCHED (VT11)'!$E:$E,'Summarized Plan'!A92)=0,"",COUNTIF('DISPATCHED (VT11)'!$E:$E,'Summarized Plan'!A92)) | Q92: =IF(A92="","",IF(ISNA(VLOOKUP(A92,'DISPATCHED (VT11)'!$E:$M,9,0)),"",VLOOKUP(A92,'DISPATCHED (VT11)'!$E:$M,9,0))) | R92: =IF(H92="","",IF(H92<#REF!,1,0)) -> #REF! | S92: =IF(H92="","",IF(H92>#REF!,1,0)) -> #REF! | T92: =IF(H92="","",IF(H92=#REF!,1,0)) -> #REF! | U92: =IF(I92="","",1) -> 1
A93: 31021616 | B93: 4K SOFTDRINKS STORE | C93: 413 | E93: 10.16 | G93: LP-PUP | H93: 46123 | M93: =VLOOKUP(B93,REFERENCE!$A$2:D306,4,0) -> ANDRE GORDONCILLO | N93: =VLOOKUP(B93,REFERENCE!A:C,3,FALSE) -> LP-PUP | O93: =COUNTIF($A:$A,A93) -> 1 | P93: =IF(COUNTIF('DISPATCHED (VT11)'!$E:$E,'Summarized Plan'!A93)=0,"",COUNTIF('DISPATCHED (VT11)'!$E:$E,'Summarized Plan'!A93)) | Q93: =IF(A93="","",IF(ISNA(VLOOKUP(A93,'DISPATCHED (VT11)'!$E:$M,9,0)),"",VLOOKUP(A93,'DISPATCHED (VT11)'!$E:$M,9,0))) | R93: =IF(H93="","",IF(H93<#REF!,1,0)) -> #REF! | S93: =IF(H93="","",IF(H93>#REF!,1,0)) -> #REF! | T93: =IF(H93="","",IF(H93=#REF!,1,0)) -> #REF! | U93: =IF(I93="","",1)
A94: 31021619 | B94: CARRY ALL FOOD ENTERPRISES INC. | C94: 784 | E94: 14 | G94: TAG-PUP | H94: 46123 | M94: =VLOOKUP(B94,REFERENCE!$A$2:D307,4,0) -> FERDINAND ALVAREZ | N94: =VLOOKUP(B94,REFERENCE!A:C,3,FALSE) -> TAG-PUP | O94: =COUNTIF($A:$A,A94) -> 1 | P94: =IF(COUNTIF('DISPATCHED (VT11)'!$E:$E,'Summarized Plan'!A94)=0,"",COUNTIF('DISPATCHED (VT11)'!$E:$E,'Summarized Plan'!A94)) | Q94: =IF(A94="","",IF(ISNA(VLOOKUP(A94,'DISPATCHED (VT11)'!$E:$M,9,0)),"",VLOOKUP(A94,'DISPATCHED (VT11)'!$E:$M,9,0))) | R94: =IF(H94="","",IF(H94<#REF!,1,0)) -> #REF! | S94: =IF(H94="","",IF(H94>#REF!,1,0)) -> #REF! | T94: =IF(H94="","",IF(H94=#REF!,1,0)) -> #REF! | U94: =IF(I94="","",1)
A95: 31021626 | B95: DOCOLA GENERAL MERCHANDISE | C95: 570 | E95: 14.07 | G95: TAG-PUP | H95: 46123 | M95: =VLOOKUP(B95,REFERENCE!$A$2:D308,4,0) -> FERDINAND ALVAREZ | N95: =VLOOKUP(B95,REFERENCE!A:C,3,FALSE) -> TAG-PUP | O95: =COUNTIF($A:$A,A95) -> 1 | P95: =IF(COUNTIF('DISPATCHED (VT11)'!$E:$E,'Summarized Plan'!A95)=0,"",COUNTIF('DISPATCHED (VT11)'!$E:$E,'Summarized Plan'!A95)) | Q95: =IF(A95="","",IF(ISNA(VLOOKUP(A95,'DISPATCHED (VT11)'!$E:$M,9,0)),"",VLOOKUP(A95,'DISPATCHED (VT11)'!$E:$M,9,0))) | R95: =IF(H95="","",IF(H95<#REF!,1,0)) -> #REF! | S95: =IF(H95="","",IF(H95>#REF!,1,0)) -> #REF! | T95: =IF(H95="","",IF(H95=#REF!,1,0)) -> #REF! | U95: =IF(I95="","",1)
A96: 31021630 | B96: GIRON STORE 2 | C96: 144 | E96: 2.57 | G96: TAG-PUP | H96: 46123 | M96: =VLOOKUP(B96,REFERENCE!$A$2:D309,4,0) -> FERDINAND ALVAREZ | N96: =VLOOKUP(B96,REFERENCE!A:C,3,FALSE) -> TAG-PUP | O96: =COUNTIF($A:$A,A96) -> 1 | P96: =IF(COUNTIF('DISPATCHED (VT11)'!$E:$E,'Summarized Plan'!A96)=0,"",COUNTIF('DISPATCHED (VT11)'!$E:$E,'Summarized Plan'!A96)) | Q96: =IF(A96="","",IF(ISNA(VLOOKUP(A96,'DISPATCHED (VT11)'!$E:$M,9,0)),"",VLOOKUP(A96,'DISPATCHED (VT11)'!$E:$M,9,0))) | R96: =IF(H96="","",IF(H96<#REF!,1,0)) -> #REF! | S96: =IF(H96="","",IF(H96>#REF!,1,0)) -> #REF! | T96: =IF(H96="","",IF(H96=#REF!,1,0)) -> #REF! | U96: =IF(I96="","",1)
A97: 31021635 | B97: PERRY AND DORY STORE | C97: 472 | E97: 3.45 | G97: PAR-PUP | H97: 46123 | M97: =VLOOKUP(B97,REFERENCE!$A$2:D310,4,0) -> RONNIE ROMERO | N97: =VLOOKUP(B97,REFERENCE!A:C,3,FALSE) -> PAR-PUP | O97: =COUNTIF($A:$A,A97) -> 1 | P97: =IF(COUNTIF('DISPATCHED (VT11)'!$E:$E,'Summarized Plan'!A97)=0,"",COUNTIF('DISPATCHED (VT11)'!$E:$E,'Summarized Plan'!A97)) | Q97: =IF(A97="","",IF(ISNA(VLOOKUP(A97,'DISPATCHED (VT11)'!$E:$M,9,0)),"",VLOOKUP(A97,'DISPATCHED (VT11)'!$E:$M,9,0))) | R97: =IF(H97="","",IF(H97<#REF!,1,0)) -> #REF! | S97: =IF(H97="","",IF(H97>#REF!,1,0)) -> #REF! | T97: =IF(H97="","",IF(H97=#REF!,1,0)) -> #REF! | U97: =IF(I97="","",1)
A98: 31021636 | B98: RETCHY STORE | C98: 240 | E98: 8 | G98: TAG-PUP | H98: 46123 | M98: =VLOOKUP(B98,REFERENCE!$A$2:D311,4,0) -> FERDINAND ALVAREZ | N98: =VLOOKUP(B98,REFERENCE!A:C,3,FALSE) -> TAG-PUP | O98: =COUNTIF($A:$A,A98) -> 1 | P98: =IF(COUNTIF('DISPATCHED (VT11)'!$E:$E,'Summarized Plan'!A98)=0,"",COUNTIF('DISPATCHED (VT11)'!$E:$E,'Summarized Plan'!A98)) | Q98: =IF(A98="","",IF(ISNA(VLOOKUP(A98,'DISPATCHED (VT11)'!$E:$M,9,0)),"",VLOOKUP(A98,'DISPATCHED (VT11)'!$E:$M,9,0))) | R98: =IF(H98="","",IF(H98<#REF!,1,0)) -> #REF! | S98: =IF(H98="","",IF(H98>#REF!,1,0)) -> #REF! | T98: =IF(H98="","",IF(H98=#REF!,1,0)) -> #REF! | U98: =IF(I98="","",1)
A99: 31021640 | B99: RVD MERCHANDISING BEVERAGE WHOLESAL | C99: 440 | E99: 7.86 | G99: LP-PUP | H99: 46123 | M99: =VLOOKUP(B99,REFERENCE!$A$2:D312,4,0) -> ANDRE GORDONCILLO | N99: =VLOOKUP(B99,REFERENCE!A:C,3,FALSE) -> LP-PUP | O99: =COUNTIF($A:$A,A99) -> 1 | P99: =IF(COUNTIF('DISPATCHED (VT11)'!$E:$E,'Summarized Plan'!A99)=0,"",COUNTIF('DISPATCHED (VT11)'!$E:$E,'Summarized Plan'!A99)) -> 1 | Q99: =IF(A99="","",IF(ISNA(VLOOKUP(A99,'DISPATCHED (VT11)'!$E:$M,9,0)),"",VLOOKUP(A99,'DISPATCHED (VT11)'!$E:$M,9,0))) -> 440 | R99: =IF(H99="","",IF(H99<#REF!,1,0)) -> #REF! | S99: =IF(H99="","",IF(H99>#REF!,1,0)) -> #REF! | T99: =IF(H99="","",IF(H99=#REF!,1,0)) -> #REF! | U99: =IF(I99="","",1)
...

Sheet Report Summary
B2: Dispatch Date: | C2: =IF('DISPATCHED (VT11)'!C4="","Please encode date on Disp Sheet",'DISPATCHED (VT11)'!C4) -> 46125 | P2: Delivery Update: 7am, 9pm, 11pm, 3pm, 5pm, and Final
P3: Send DP Update: 12:30pm
A4: A. Load Out: | H4: A1. Load Out Breakdown: | O4: A2. Text Update:
B6: Summary | C6: Shipments | E6: Physical Cases | G6: Efficiency | I6: KA | J6: Shipments | L6: Physical Cases | N6: Efficiency | P6: Summary | R6: Trip dispatched | X6: Summary | Y6: TARGETS
C7: Planned | D7: Dispatched | E7: Planned | F7: Dispatched | J7: Planned | K7: Dispatched | L7: Planned | M7: Dispatched | R7: Planned | S7: Dispatched | T7: Variance | U7: Efficiency | Y7: 7AM Dispatched | Z7: Trippage | AA7: Dispatched | AB7: Truck Allocated | AC7: Trippage | AF7: Plan | AH7: Actual | AJ7: % | AL7: Balance | AN7: Remarks
B8: Current | C8: =R8+R11+R14+R17+R20+R23+R26 -> 186 | D8: =S8+S11+S14+S17+S20+S23+S26 -> 83 | E8: =R39+R42+R45+R48+R51+R54+R57 -> 58799 | F8: =S39+S42+S45+S48+S51+S54+S57 -> 21736 | G8: =IF(ISERROR(D8/C8),"-",D8/C8) -> 0.44623656 | I8: Current | J8: =COUNTIFS('Summarized Plan'!$G:$G,'Report Summary'!I6,'Summarized Plan'!$H:$H,'Report Summary'!$C$2) -> 89 | K8: =SUMIFS('Summarized Plan'!$P:$P,'Summarized Plan'!$G:$G,'Report Summary'!I6,'Summarized Plan'!$H:$H,'Report Summary'!C2) -> 57 | L8: =SUMIFS('Summarized Plan'!$C:$C,'Summarized Plan'!$G:$G,'Report Summary'!I6,'Summarized Plan'!$H:$H,'Report Summary'!$C$2) -> 25665 | M8: =SUMIFS('Summarized Plan'!$Q:$Q,'Summarized Plan'!$G:$G,'Report Summary'!I6,'Summarized Plan'!$H:$H,'Report Summary'!$C$2) -> 14252 | N8: =IF(ISERROR(K8/J8),"-",K8/J8) -> 0.64044944 | O8: =R8+R11+R14+R17+R20+R23+R9+R12+R15+R18+R21+R24 -> #REF! | P8: KA | Q8: CURRENT | R8: =+J8 -> 89 | S8: =K8 -> 57 | T8: =R8-S8 -> 32 | U8: =S8/R8 -> 0.64044944 | W8: =+AB8*Z8 -> 48.4 | X8: KA | Y8: =IF((R8+R9)<ROUNDDOWN((AB8*0.8),0),(R8+R9),ROUNDDOWN((AB8*0.8),0)) -> #REF! | Z8: 1.1 | AA8: =+S8+S9 -> 57 | AB8: =44 -> 44 | AC8: =+(S8+S9)/AB8 -> 1.2954545 | AF8: Shipments | AG8: cases | AH8: Shipments | AI8: cases | AJ8: Shipments | AK8: cases | AL8: Shipments | AM8: cases | AX8: =C2 -> 46125
B9: Backlogs | C9: =R9+R12+R15+R18+R21+R24+R27 -> #REF! | D9: =S9+S12+S15+S18+S21+S24+S27 -> 0 | E9: =R40+R43+R46+R49+R52+R55+R58 -> 0 | F9: =S40+S43+S46+S49+S52+S55+S58 -> 0 | G9: =IF(ISERROR(D9/C9),"-",D9/C9) -> - | I9: Backlogs | J9: =SUMIF('Summarized Plan'!$G:$G,'Report Summary'!I6,'Summarized Plan'!$R:$R) -> #REF! | K9: =SUMIFS('Summarized Plan'!$P:$P,'Summarized Plan'!$R:$R,"=1",'Summarized Plan'!$G:$G,'Report Summary'!I6) -> 0 | L9: =SUMIFS('Summarized Plan'!$C:$C,'Summarized Plan'!$R:$R,"=1",'Summarized Plan'!$G:$G,'Report Summary'!I6) -> 0 | M9: =SUMIFS('Summarized Plan'!$Q:$Q,'Summarized Plan'!$R:$R,"=1",'Summarized Plan'!$G:$G,'Report Summary'!I6) -> 0 | N9: =IF(ISERROR(K9/J9),"-",K9/J9) -> - | O9: =S8+S11+S14+S17+S20+S23+S9+S12+S15+S18+S21+S24 -> 80 | Q9: BACKLOG | R9: =J9 -> #REF! | S9: =K9 -> 0 | T9: =R9-S9 -> #REF! | U9: =S9/R9 -> #REF! | AE9: KA | AF9: =R8+R9 -> #REF! | AG9: =R39+R40 -> 25665 | AH9: =S8+S9 -> 57 | AI9: =S39+S40 -> 14252 | AJ9: =AH9/AF9 -> #REF! | AK9: =AI9/AG9 -> 0.55530879 | AL9: =AF9-AH9 -> #REF! | AM9: =AG9-AI9 -> 11413 | AX9: Dated | AY9: In Shipment | BB9: In PCS | BF9: In UCS
B10: Advanced | C10: =R10+R13+R16+R19+R22+R25+R28 -> #REF! | D10: =S10+S13+S16+S19+S22+S25+S28 -> 0 | E10: =R41+R44+R47+R50+R53+R56+R59 -> 0 | F10: =S41+S44+S47+S50+S53+S56+S59 -> 0 | G10: =IF(ISERROR(D10/C10),"-",D10/C10) -> - | I10: Advanced | J10: =SUMIF('Summarized Plan'!$G:$G,'Report Summary'!I6,'Summarized Plan'!$S:$S) -> #REF! | K10: =SUMIFS('Summarized Plan'!$P:$P,'Summarized Plan'!$S:$S,"=1",'Summarized Plan'!$G:$G,'Report Summary'!I6) -> 0 | L10: =SUMIFS('Summarized Plan'!$C:$C,'Summarized Plan'!$S:$S,"=1",'Summarized Plan'!$G:$G,'Report Summary'!I6) -> 0 | M10: =SUMIFS('Summarized Plan'!$Q:$Q,'Summarized Plan'!$S:$S,"=1",'Summarized Plan'!$G:$G,'Report Summary'!I6) -> 0 | N10: =IF(ISERROR(K10/J10),"-",K10/J10) -> - | Q10: ADVANCE | R10: =J10 -> #REF! | S10: =K10 -> 0 | T10: =R10-S10 -> #REF! | U10: =S10/R10 -> #REF! | W10: =+AB10*Z10 -> 1 | X10: DSD | Y10: =IF((R11+R12)<ROUNDDOWN((AB10*0.8),0),(R11+R12),ROUNDDOWN((AB10*0.8),0)) -> #REF! | Z10: 1 | AA10: =+S11+S12 -> 3 | AB10: 1 | AC10: =+(S11+S12)/AB10 -> 3 | AE10: DP | AF10: =R14+R15 -> #REF! | AG10: =R45+R46 -> 7184 | AH10: =S14+S15 -> 6 | AI10: =S45+S46 -> 1495 | AJ10: =AH10/AF10 -> #REF! | AK10: =AI10/AG10 -> 0.20810134 | AL10: =AF10-AH10 -> #REF! | AM10: =AG10-AI10 -> 5689 | AX10: Source | AY10: Plan | AZ10: Executed | BA10: Balance | BB10: Plan | BC10: Executed | BD10: Balance | BE10: Loadout | BF10: Plan | BG10: Executed | BH10: Balance | BI10: Loadout
B11: Total | C11: =SUM(C8:C10) -> #REF! | D11: =SUM(D8:D10) -> 83 | E11: =SUM(E8:E10) -> 58799 | F11: =S42+S45+S48+S51+S54+S57+S60 -> 7484 | G11: =IF(ISERROR(D11/C11),"-",D11/C11) -> - | I11: Total | J11: =SUM(J8:J10) -> #REF! | K11: =SUM(K8:K10) -> 57 | L11: =SUM(L8:L10) -> 25665 | M11: =SUM(M8:M10) -> 14252 | N11: =IF(ISERROR(K11/J11),"-",K11/J11) -> - | P11: HOD | Q11: CURRENT | R11: =J15 -> 11 | S11: =K15 -> 3 | T11: =R11-S11 -> 8 | U11: =S11/R11 -> 0.27272727 | AE11: DSD | AF11: =R11+R12 -> #REF! | AG11: =R42 -> 3504 | AH11: =S11 -> 3 | AI11: =S42 -> 921 | AJ11: =AH11/AF11 -> #REF! | AK11: =AI11/AG11 -> 0.26284247 | AL11: =AF11-AH11 -> #REF! | AM11: =AG11-AI11 -> 2583 | AX11: Manila | BI11: =IFERROR(BG11/BF11,"")
Q12: BACKLOG | R12: =J16 -> #REF! | S12: =K16 -> 0 | T12: =R12-S12 -> #REF! | U12: =S12/R12 -> #REF! | W12: =+AB12*Z12 -> 128 | X12: DP | Y12: =IF((R14+R15)<ROUNDDOWN((AB12*0.8),0),(R14+R15),ROUNDDOWN((AB12*0.8),0)) -> #REF! | Z12: 2 | AA12: =+S14+S15 -> 6 | AB12: =64 -> 64 | AC12: =+(S14+S15)/AB12 -> 0.09375 | AE12: KOFD | AF12: =R17+R18 -> #REF! | AG12: =R48+R49 -> 1900 | AH12: =S17+S18 -> 3 | AI12: =S48+S49 -> 777 | AJ12: =AH12/AF12 -> #REF! | AK12: =AI12/AG12 -> 0.40894737 | AL12: =AF12-AH12 -> #REF! | AM12: =AG12-AI12 -> 1123 | AX12: Parañaque | AY12: =+R8+R11+R14+R17+R20+R23+R29 -> 156 | AZ12: =+S8+S11+S14+S17+S20+S23+S29 -> 80 | BA12: =+AY12-AZ12 -> 76 | BI12: =IFERROR(BG12/BF12,"")
A13: B. DSR Attendance (CCBPI): | I13: HOD | J13: Shipments | L13: Physical Cases | N13: Efficiency | Q13: ADVANCE | R13: =J17 -> #REF! | S13: =K17 -> 0 | T13: =R13-S13 -> #REF! | U13: =S13/R13 -> #REF! | AE13: WS | AF13: =R20+R21 -> #REF! | AG13: =R51+R52 -> 5796 | AH13: =S20+S21 -> 11 | AI13: =S51+S52 -> 3003 | AJ13: =AH13/AF13 -> #REF! | AK13: =AI13/AG13 -> 0.51811594 | AL13: =AF13-AH13 -> #REF! | AY13: =SUM(AY11:AY12) -> 156 | AZ13: =SUM(AZ11:AZ12) -> 80 | BA13: =SUM(BA11:BA12) -> 76 | BB13: =SUM(BB11:BB12) -> 0 | BC13: =SUM(BC11:BC12) -> 0 | BD13: =SUM(BD11:BD12) -> 0 | BE13: =SUM(BE11:BE12) -> 0 | BF13: =SUM(BF11:BF12) -> 0 | ... BI13: =SUM(BI11:BI12) -> 0
J14: Planned | K14: Dispatched | L14: Planned | M14: Dispatched | P14: DP | Q14: CURRENT | R14: =J22+J29+J36+J43+J50+J183 -> 27 | S14: =K22+K29+K36+K43+K50+K183 -> 6 | T14: =R14-S14 -> 21 | U14: =S14/R14 -> 0.22222222 | W14: =+AB14*Z14 -> 2 | X14: KOF | Y14: =IF((R17+R18)<ROUNDDOWN((AB14*0.8),0),(R17+R18),ROUNDDOWN((AB14*0.8),0)) -> #REF! | Z14: 2 | AA14: =+S17+S18 -> 3 | AB14: 1 | AC14: =+(S17+S18)/AB14 -> 3 | AE14: Total | AF14: =SUM(AF9:AF13) -> #REF! | AG14: =SUM(AG9:AG13) -> 44049 | AH14: =SUM(AH9:AH13) -> 80 | AI14: =SUM(AI9:AI13) -> 20448 | AJ14: =AH14/AF14 -> #REF! | AK14: =AI14/AG14 -> 0.46421031 | AL14: =SUM(AL9:AL13) -> #REF! | AM14: =SUM(AM9:AM13) -> 20808
B15: Manning | C15: Number | F15: Absentism Rate | I15: Current | J15: =COUNTIFS('Summarized Plan'!$G:$G,'Report Summary'!I13,'Summarized Plan'!$H:$H,'Report Summary'!$C$2) -> 11 | K15: =SUMIFS('Summarized Plan'!$P:$P,'Summarized Plan'!$G:$G,'Report Summary'!I13,'Summarized Plan'!$H:$H,'Report Summary'!$C$2) -> 3 | L15: =SUMIFS('Summarized Plan'!$C:$C,'Summarized Plan'!$G:$G,'Report Summary'!I13,'Summarized Plan'!$H:$H,'Report Summary'!$C$2) -> 3504 | M15: =SUMIFS('Summarized Plan'!$Q:$Q,'Summarized Plan'!$G:$G,'Report Summary'!I13,'Summarized Plan'!$H:$H,'Report Summary'!$C$2) -> 921 | N15: =IF(ISERROR(K15/J15),"-",K15/J15) -> 0.27272727 | Q15: BACKLOG | R15: =J23+J30+J37+J44+J44+J51+J184 -> #REF! | S15: =K23+K30+K37+K44+K44+K51+K184 -> 0 | T15: =R15-S15 -> #REF! | U15: =S15/R15 -> #REF! | AI15: AGAG15:AI34
C16: Expected | D16: Reported | E16: Variance | I16: Backlogs | J16: =SUMIF('Summarized Plan'!$G:$G,'Report Summary'!I13,'Summarized Plan'!$R:$R) -> #REF! | K16: =SUMIFS('Summarized Plan'!$P:$P,'Summarized Plan'!$R:$R,"=1",'Summarized Plan'!$G:$G,'Report Summary'!I13) -> 0 | L16: =SUMIFS('Summarized Plan'!$C:$C,'Summarized Plan'!$R:$R,"=1",'Summarized Plan'!$G:$G,'Report Summary'!I13) -> 0 | M16: =SUMIFS('Summarized Plan'!$Q:$Q,'Summarized Plan'!$R:$R,"=1",'Summarized Plan'!$G:$G,'Report Summary'!I13) -> 0 | N16: =IF(ISERROR(K16/J16),"-",K16/J16) -> - | Q16: ADVANCE | R16: =J24+J31+J38+J45+J52+J185 -> #REF! | S16: =K24+K31+K38+K45+K52+K185 -> 0 | T16: =R16-S16 -> #REF! | U16: =S16/R16 -> #REF! | W16: =+AB16*Z16 -> 0 | X16: WS | Y16: =IF((R20+R21)<ROUNDDOWN((AB16*0.8),0),(R20+R21),ROUNDDOWN((AB16*0.8),0)) -> #REF! | Z16: 1.5 | AA16: =+S20+S21 -> 11 | AB16: 0 | AC16: =+(S20+S21)/AB16 -> #DIV/0! | AE16: Parañaque DC | AG16: Trip Dispatched | AJ16: Volume Loadout | AM16: PERCENT ACHIEVED | AN16: ASSIGNED DRIVER | AR16: Replacement DSR | AS16: SALES EXECUTIVE | AT16: REGION SALES MANAGER
B17: CCBPI | C17: =COUNTIF('DSR Attendance'!$B:$B,"=CCBPI") -> 109 | D17: =SUMIF('DSR Attendance'!$B:$B,"=CCBPI",'DSR Attendance'!$C:$C) -> 44 | E17: =+C17-D17 -> 65 | F17: =+D17/C17 -> 0.40366972 | I17: Advanced | J17: =SUMIF('Summarized Plan'!$G:$G,'Report Summary'!I13,'Summarized Plan'!$S:$S) -> #REF! | K17: =SUMIFS('Summarized Plan'!$P:$P,'Summarized Plan'!$S:$S,"=1",'Summarized Plan'!$G:$G,'Report Summary'!I13) -> 0 | L17: =SUMIFS('Summarized Plan'!$C:$C,'Summarized Plan'!$S:$S,"=1",'Summarized Plan'!$G:$G,'Report Summary'!I13) -> 0 | M17: =SUMIFS('Summarized Plan'!$Q:$Q,'Summarized Plan'!$S:$S,"=1",'Summarized Plan'!$G:$G,'Report Summary'!I13) -> 0 | N17: =IF(ISERROR(K17/J17),"-",K17/J17) -> - | P17: LWS | Q17: CURRENT | R17: =J57+J64+J71+J78+J85+J190 -> 8 | S17: =K57+K64+K71+K78+K85+K190 -> 3 | T17: =R17-S17 -> 5 | U17: =S17/R17 -> 0.375 | AG17: Planned | AH17: Dispatched | AI17: Balance | AJ17: Planned | AK17: Dispatched | AL17: Balance | AN17: DRIVER 1 | AO17: DRIVER 2 | AP17: DRIVER 3 | AQ17: DRIVER 4
B18: Casual | C18: =COUNTIF('DSR Attendance'!$B:$B,"=CCBPI - CASUAL") -> 0 | D18: =SUMIF('DSR Attendance'!$B:$B,"=TRCI -",'DSR Attendance'!$C:$C) -> 0 | E18: =+C18-D18 -> 0 | F18: =+D18/C18 -> #DIV/0! | I18: Total | J18: =SUM(J15:J17) -> #REF! | K18: =SUM(K15:K17) -> 3 | L18: =SUM(L15:L17) -> 3504 | M18: =SUM(M15:M17) -> 921 | N18: =IF(ISERROR(K18/J18),"-",K18/J18) -> - | Q18: BACKLOG | R18: =J58+J65+J72+J79+J86+J191 -> #REF! | S18: =K58+K65+K72+K79+K86 -> 0 | T18: =R18-S18 -> #REF! | U18: =S18/R18 -> #REF! | AG18: =SUMIF('Summarized Plan'!#REF!,$AE18,'Summarized Plan'!#REF!) -> #REF! | AH18: =SUMIF('Summarized Plan'!#REF!,$AE18,'Summarized Plan'!#REF!) -> #REF! | AI18: =AG18-AH18 -> #REF! | AJ18: =SUMIF('Summarized Plan'!#REF!,$AE18,'Summarized Plan'!#REF!) -> #REF! | AK18: =SUMIF('Summarized Plan'!#REF!,$AE18,'Summarized Plan'!#REF!) -> #REF! | AL18: =AJ18-AK18 -> #REF! | AM18: =AH18/AG18 -> #REF!
B19: Total | C19: =+SUM(C17:C18) -> 109 | D19: =+SUM(D17:D18) -> 44 | E19: =+SUM(E17:E18) -> 65 | F19: =+D19/C19 -> 0.40366972 | Q19: ADVANCE | R19: =J59+J66+J73+J80+J87+J192 -> #REF! | S19: =K59+K66+K73+K80+K87+K192 -> 0 | T19: =R19-S19 -> #REF! | U19: =S19/R19 -> #REF! | AG19: =SUM(AG18) -> #REF! | AH19: =SUM(AH18) -> #REF! | AI19: =AG19-AH19 -> #REF! | AJ19: =SUM(AJ18) -> #REF! | AK19: =SUM(AK18) -> #REF! | AL19: =AJ19-AK19 -> #REF! | AM19: =AH19/AG19 -> #REF!
I20: BAG-DP | J20: Shipments | L20: Physical Cases | N20: Efficiency | P20: WS | Q20: CURRENT | R20: =J92+J99+J106+J113+J120+J162+J197 -> 21 | S20: =K92+K99+K106+K113+K120+K162+K197 -> 11 | T20: =R20-S20 -> 10 | U20: =S20/R20 -> 0.52380952 | AE20: DP MAGNUM | AG20: =SUMIF('Summarized Plan'!#REF!,$AE20,'Summarized Plan'!#REF!) -> #REF! | AH20: =SUMIF('Summarized Plan'!#REF!,$AE20,'Summarized Plan'!#REF!) -> #REF! | AI20: =AG20-AH20 -> #REF! | AJ20: =SUMIF('Summarized Plan'!#REF!,$AE20,'Summarized Plan'!#REF!) -> #REF! | AK20: =SUMIF('Summarized Plan'!#REF!,$AE20,'Summarized Plan'!#REF!) -> #REF! | AL20: =AJ20-AK20 -> #REF! | AM20: =AH20/AG20 -> #REF!
A21: C. DSR Attendance (TPD): | J21: Planned | K21: Dispatched | L21: Planned | M21: Dispatched | Q21: BACKLOG | R21: =J93+J100+J107+J114+J121+J163+J198 -> #REF! | S21: =K93+K100+K107+K114+K121+K163+K198 -> 0 | T21: =R21-S21 -> #REF! | U21: =S21/R21 -> #REF! | AE21: DP ASH JACK TRADING | AG21: =SUMIF('Summarized Plan'!#REF!,$AE21,'Summarized Plan'!#REF!) -> #REF! | AH21: =SUMIF('Summarized Plan'!#REF!,$AE21,'Summarized Plan'!#REF!) -> #REF! | AI21: =AG21-AH21 -> #REF! | AJ21: =SUMIF('Summarized Plan'!#REF!,$AE21,'Summarized Plan'!#REF!) -> #REF! | AK21: =SUMIF('Summarized Plan'!#REF!,$AE21,'Summarized Plan'!#REF!) -> #REF! | AL21: =AJ21-AK21 -> #REF! | AM21: =AH21/AG21 -> #REF!
I22: Current | J22: =COUNTIFS('Summarized Plan'!$G:$G,'Report Summary'!I20,'Summarized Plan'!$H:$H,'Report Summary'!$C$2) -> 0 | K22: =SUMIFS('Summarized Plan'!$P:$P,'Summarized Plan'!$G:$G,'Report Summary'!I20,'Summarized Plan'!$H:$H,'Report Summary'!$C$2) -> 0 | L22: =SUMIFS('Summarized Plan'!$C:$C,'Summarized Plan'!$G:$G,'Report Summary'!I20,'Summarized Plan'!$H:$H,'Report Summary'!$C$2) -> 0 | M22: =SUMIFS('Summarized Plan'!$Q:$Q,'Summarized Plan'!$G:$G,'Report Summary'!I20,'Summarized Plan'!$H:$H,'Report Summary'!$C$2) -> 0 | N22: =IF(ISERROR(K22/J22),"-",K22/J22) -> - | Q22: ADVANCE | R22: =J94+J101+J108+J115+J122+J164+J199 -> #REF! | S22: =K94+K101+K108+K115+K122+K164+K199 -> 0 | T22: =R22-S22 -> #REF! | U22: =S22/R22 -> #REF! | AE22: DP L.A.V TRADING | AG22: =SUMIF('Summarized Plan'!#REF!,$AE22,'Summarized Plan'!#REF!) -> #REF! | AH22: =SUMIF('Summarized Plan'!#REF!,$AE22,'Summarized Plan'!#REF!) -> #REF! | AI22: =AG22-AH22 -> #REF! | AJ22: =SUMIF('Summarized Plan'!#REF!,$AE22,'Summarized Plan'!#REF!) -> #REF! | AK22: =SUMIF('Summarized Plan'!#REF!,$AE22,'Summarized Plan'!#REF!) -> #REF! | AL22: =AJ22-AK22 -> #REF! | AM22: =AH22/AG22 -> #REF!
B23: Manning | C23: Number | F23: Absentism Rate | I23: Backlogs | J23: =SUMIF('Summarized Plan'!$G:$G,'Report Summary'!I20,'Summarized Plan'!$R:$R) -> 0 | K23: =SUMIFS('Summarized Plan'!$P:$P,'Summarized Plan'!$R:$R,"=1",'Summarized Plan'!$G:$G,'Report Summary'!I20) -> 0 | L23: =SUMIFS('Summarized Plan'!$C:$C,'Summarized Plan'!$R:$R,"=1",'Summarized Plan'!$G:$G,'Report Summary'!I20) -> 0 | M23: =SUMIFS('Summarized Plan'!$Q:$Q,'Summarized Plan'!$R:$R,"=1",'Summarized Plan'!$G:$G,'Report Summary'!I20) -> 0 | N23: =IF(ISERROR(K23/J23),"-",K23/J23) -> - | P23: DIRECTSHIP | Q23: CURRENT | R23: =J169 -> 0 | S23: =K169 -> 0 | T23: =R23-S23 -> 0 | U23: =S23/R23 -> #DIV/0! | AE23: DP MAY SANTOS TRADING | AG23: =SUMIF('Summarized Plan'!#REF!,$AE23,'Summarized Plan'!#REF!) -> #REF! | AH23: =SUMIF('Summarized Plan'!#REF!,$AE23,'Summarized Plan'!#REF!) -> #REF! | AI23: =AG23-AH23 -> #REF! | AJ23: =SUMIF('Summarized Plan'!#REF!,$AE23,'Summarized Plan'!#REF!) -> #REF! | AK23: =SUMIF('Summarized Plan'!#REF!,$AE23,'Summarized Plan'!#REF!) -> #REF! | AL23: =AJ23-AK23 -> #REF! | AM23: =AH23/AG23 -> #REF!
C24: Expected | D24: Reported | E24: Variance | I24: Advanced | J24: =SUMIF('Summarized Plan'!$G:$G,'Report Summary'!I20,'Summarized Plan'!$S:$S) -> 0 | K24: =SUMIFS('Summarized Plan'!$P:$P,'Summarized Plan'!$S:$S,"=1",'Summarized Plan'!$G:$G,'Report Summary'!I20) -> 0 | L24: =SUMIFS('Summarized Plan'!$C:$C,'Summarized Plan'!$S:$S,"=1",'Summarized Plan'!$G:$G,'Report Summary'!I20) -> 0 | M24: =SUMIFS('Summarized Plan'!$Q:$Q,'Summarized Plan'!$S:$S,"=1",'Summarized Plan'!$G:$G,'Report Summary'!I20) -> 0 | N24: =IF(ISERROR(K24/J24),"-",K24/J24) -> - | Q24: BACKLOG | R24: =J170 -> 0 | S24: =K170 -> 0 | T24: =R24-S24 -> 0 | U24: =S24/R24 -> #DIV/0! | AE24: DP RICAFORTZ CONSUMER GOODS TRADING | AG24: =SUMIF('Summarized Plan'!#REF!,$AE24,'Summarized Plan'!#REF!) -> #REF! | AH24: =SUMIF('Summarized Plan'!#REF!,$AE24,'Summarized Plan'!#REF!) -> #REF! | AI24: =AG24-AH24 -> #REF! | AJ24: =SUMIF('Summarized Plan'!#REF!,$AE24,'Summarized Plan'!#REF!) -> #REF! | AK24: =SUMIF('Summarized Plan'!#REF!,$AE24,'Summarized Plan'!#REF!) -> #REF! | AL24: =AJ24-AK24 -> #REF! | AM24: =AH24/AG24 -> #REF!
B25: ONG | C25: =COUNTIF('DSR Attendance'!$B:$B,B25) -> 19 | D25: =SUMIF('DSR Attendance'!$B:$B,B25,'DSR Attendance'!$C:$C) -> 8 | E25: =+C25-D25 -> 11 | F25: =+D25/C25 -> 0.42105263 | I25: Total | J25: =SUM(J22:J24) -> 0 | K25: =SUM(K22:K24) -> 0 | L25: =SUM(L22:L24) -> 0 | M25: =SUM(M22:M24) -> 0 | N25: =IF(ISERROR(K25/J25),"-",K25/J25) -> - | Q25: ADVANCE | R25: =J171 -> 0 | S25: =K171 -> 0 | T25: =R25-S25 -> 0 | U25: =S25/R25 -> #DIV/0! | W25: =SUM(W8:W16) -> 179.4 | X25: Total | Y25: =IF((R32+R33)<SUM(Y8:Y19),R32+R33,SUM(Y8:Y19)) -> #REF! | Z25: =+W25/AB25 -> 1.6309091 | AA25: =SUM(AA16,AA12,AA14,AA8,AA10) -> 80 | AB25: =SUM(AB8:AB16) -> 110 | AC25: =+(S32+S33)/AB25 -> 0.75454545 | AG25: =SUMIF('Summarized Plan'!#REF!,$AE25,'Summarized Plan'!#REF!) -> #REF! | AH25: =SUMIF('Summarized Plan'!#REF!,$AE25,'Summarized Plan'!#REF!) -> #REF! | AI25: =AG25-AH25 -> #REF! | AJ25: =SUMIF('Summarized Plan'!#REF!,$AE25,'Summarized Plan'!#REF!) -> #REF! | AK25: =SUMIF('Summarized Plan'!#REF!,$AE25,'Summarized Plan'!#REF!) -> #REF! | AL25: =AJ25-AK25 -> #REF! | AM25: =AH25/AG25 -> #REF!
B26: RRAJ | C26: =COUNTIF('DSR Attendance'!$B:$B,B26) -> 22 | D26: =SUMIF('DSR Attendance'!$B:$B,B26,'DSR Attendance'!$C:$C) -> 9 | E26: =+C26-D26 -> 13 | F26: =+D26/C26 -> 0.40909091 | O26: =R26+R27 -> #REF! | P26: PICK UP | Q26: CURRENT | R26: =J127+J134+J141+J148+J155+J204 -> 30 | S26: =K127+K134+K141+K148+K155+K204 -> 3 | T26: =R26-S26 -> 27 | U26: =S26/R26 -> 0.1 | AG26: =SUMIF('Summarized Plan'!#REF!,$AE26,'Summarized Plan'!#REF!) -> #REF! | AH26: =SUMIF('Summarized Plan'!#REF!,$AE26,'Summarized Plan'!#REF!) -> #REF! | AI26: =AG26-AH26 -> #REF! | AJ26: =SUMIF('Summarized Plan'!#REF!,$AE26,'Summarized Plan'!#REF!) -> #REF! | AK26: =SUMIF('Summarized Plan'!#REF!,$AE26,'Summarized Plan'!#REF!) -> #REF! | AL26: =AJ26-AK26 -> #REF! | AM26: =AH26/AG26 -> #REF!
B27: 2GO | C27: =COUNTIF('DSR Attendance'!$B:$B,B27) -> 0 | D27: =SUMIF('DSR Attendance'!$B:$B,B27,'DSR Attendance'!$C:$C) -> 0 | E27: =+C27-D27 -> 0 | F27: =+D27/C27 -> #DIV/0! | I27: LP-DP | J27: Shipments | L27: Physical Cases | N27: Efficiency | O27: =S26+S27 -> 3 | Q27: BACKLOG | R27: =J128+J135+J142+J149+J156+J205 -> #REF! | S27: =K128+K135+K142+K149+K156+K205 -> 0 | T27: =R27-S27 -> #REF! | U27: =S27/R27 -> #REF! | AG27: =SUMIF('Summarized Plan'!#REF!,$AE27,'Summarized Plan'!#REF!) -> #REF! | AH27: =SUMIF('Summarized Plan'!#REF!,$AE27,'Summarized Plan'!#REF!) -> #REF! | AI27: =AG27-AH27 -> #REF! | AJ27: =SUMIF('Summarized Plan'!#REF!,$AE27,'Summarized Plan'!#REF!) -> #REF! | AK27: =SUMIF('Summarized Plan'!#REF!,$AE27,'Summarized Plan'!#REF!) -> #REF! | AL27: =AJ27-AK27 -> #REF! | AM27: =AH27/AG27 -> #REF!
B28: A-TRANS LOG | C28: =COUNTIF('DSR Attendance'!$B:$B,B28) -> 0 | D28: =SUMIF('DSR Attendance'!$B:$B,B28,'DSR Attendance'!$C:$C) -> 0 | E28: =+C28-D28 -> 0 | F28: =+D28/C28 -> #DIV/0! | J28: Planned | K28: Dispatched | L28: Planned | M28: Dispatched | Q28: ADVANCE | R28: =J129+J136+J143+J150+J157+J206 -> #REF! | S28: =K129+K136+K143+K150+K157+K206 -> 0 | T28: =R28-S28 -> #REF! | U28: =S28/R28 -> #REF! | AG28: =SUMIF('Summarized Plan'!#REF!,$AE28,'Summarized Plan'!#REF!) -> #REF! | AH28: =SUMIF('Summarized Plan'!#REF!,$AE28,'Summarized Plan'!#REF!) -> #REF! | AI28: =AG28-AH28 -> #REF! | AJ28: =SUMIF('Summarized Plan'!#REF!,$AE28,'Summarized Plan'!#REF!) -> #REF! | AK28: =SUMIF('Summarized Plan'!#REF!,$AE28,'Summarized Plan'!#REF!) -> #REF! | AL28: =AJ28-AK28 -> #REF! | AM28: =AH28/AG28 -> #REF!
B29: EMME | C29: =COUNTIF('DSR Attendance'!$B:$B,B29) -> 0 | D29: =SUMIF('DSR Attendance'!$B:$B,B29,'DSR Attendance'!$C:$C) -> 0 | E29: =+C29-D29 -> 0 | F29: =+D29/C29 -> #DIV/0! | I29: Current | J29: =COUNTIFS('Summarized Plan'!$G:$G,'Report Summary'!I27,'Summarized Plan'!$H:$H,'Report Summary'!$C$2) -> 20 | K29: =SUMIFS('Summarized Plan'!$P:$P,'Summarized Plan'!$G:$G,'Report Summary'!I27,'Summarized Plan'!$H:$H,'Report Summary'!$C$2) -> 3 | L29: =SUMIFS('Summarized Plan'!$C:$C,'Summarized Plan'!$G:$G,'Report Summary'!I27,'Summarized Plan'!$H:$H,'Report Summary'!$C$2) -> 5594 | M29: =SUMIFS('Summarized Plan'!$Q:$Q,'Summarized Plan'!$G:$G,'Report Summary'!I27,'Summarized Plan'!$H:$H,'Report Summary'!$C$2) -> 852 | N29: =IF(ISERROR(K29/J29),"-",K29/J29) -> 0.15 | P29: KOFD | Q29: CURRENT | R29: =J176 -> 0 | S29: =K176 -> 0 | T29: =R29-S29 -> 0 | U29: =S29/R29 -> #DIV/0! | AG29: =SUMIF('Summarized Plan'!#REF!,$AE29,'Summarized Plan'!#REF!) -> #REF! | AH29: =SUMIF('Summarized Plan'!#REF!,$AE29,'Summarized Plan'!#REF!) -> #REF! | AI29: =AG29-AH29 -> #REF! | AJ29: =SUMIF('Summarized Plan'!#REF!,$AE29,'Summarized Plan'!#REF!) -> #REF! | AK29: =SUMIF('Summarized Plan'!#REF!,$AE29,'Summarized Plan'!#REF!) -> #REF! | AL29: =AJ29-AK29 -> #REF! | AM29: =AH29/AG29 -> #REF!
B30: AMOURE | C30: =COUNTIF('DSR Attendance'!$B:$B,B30) -> 0 | D30: =SUMIF('DSR Attendance'!$B:$B,B30,'DSR Attendance'!$C:$C) -> 0 | E30: =+C30-D30 -> 0 | F30: =+D30/C30 -> #DIV/0! | I30: Backlogs | J30: =SUMIF('Summarized Plan'!$G:$G,'Report Summary'!I27,'Summarized Plan'!$R:$R) -> #REF! | K30: =SUMIFS('Summarized Plan'!$P:$P,'Summarized Plan'!$R:$R,"=1",'Summarized Plan'!$G:$G,'Report Summary'!I27) -> 0 | L30: =SUMIFS('Summarized Plan'!$C:$C,'Summarized Plan'!$R:$R,"=1",'Summarized Plan'!$G:$G,'Report Summary'!I27) -> 0 | M30: =SUMIFS('Summarized Plan'!$Q:$Q,'Summarized Plan'!$R:$R,"=1",'Summarized Plan'!$G:$G,'Report Summary'!I27) -> 0 | N30: =IF(ISERROR(K30/J30),"-",K30/J30) -> - | Q30: BACKLOG | R30: =J177 -> 0 | S30: =K177 -> 0 | T30: =R30-S30 -> 0 | U30: =S30/R30 -> #DIV/0! | AG30: =SUM(AG20:AG29) -> #REF! | AH30: =SUM(AH20:AH29) -> #REF! | AI30: =SUM(AI20:AI29) -> #REF! | AJ30: =SUM(AJ20:AJ29) -> #REF! | AK30: =SUM(AK20:AK29) -> #REF! | AL30: =SUM(AL20:AL29) -> #REF! | AM30: =AH30/AG30 -> #REF!
I31: Advanced | J31: =SUMIF('Summarized Plan'!$G:$G,'Report Summary'!I27,'Summarized Plan'!$S:$S) -> #REF! | K31: =SUMIFS('Summarized Plan'!$P:$P,'Summarized Plan'!$S:$S,"=1",'Summarized Plan'!$G:$G,'Report Summary'!I27) -> 0 | L31: =SUMIFS('Summarized Plan'!$C:$C,'Summarized Plan'!$S:$S,"=1",'Summarized Plan'!$G:$G,'Report Summary'!I27) -> 0 | M31: =SUMIFS('Summarized Plan'!$Q:$Q,'Summarized Plan'!$S:$S,"=1",'Summarized Plan'!$G:$G,'Report Summary'!I27) -> 0 | N31: =IF(ISERROR(K31/J31),"-",K31/J31) -> - | Q31: ADVANCE | R31: =J178 -> 0 | S31: =K178 -> 0 | T31: =R31-S31 -> 0 | U31: =S31/R31 -> #DIV/0! | AE31: DP COSMICLOAD INC. | AG31: =SUMIF('Summarized Plan'!#REF!,$AE31,'Summarized Plan'!#REF!) -> #REF! | AH31: =SUMIF('Summarized Plan'!#REF!,$AE31,'Summarized Plan'!#REF!) -> #REF! | AI31: =AG31-AH31 -> #REF! | AJ31: =SUMIF('Summarized Plan'!#REF!,$AE31,'Summarized Plan'!#REF!) -> #REF! | AK31: =SUMIF('Summarized Plan'!#REF!,$AE31,'Summarized Plan'!#REF!) -> #REF! | AL31: =AJ31-AK31 -> #REF! | AM31: =AH31/AG31 -> #REF!
I32: Total | J32: =SUM(J29:J31) -> #REF! | K32: =SUM(K29:K31) -> 3 | L32: =SUM(L29:L31) -> 5594 | M32: =SUM(M29:M31) -> 852 | N32: =IF(ISERROR(K32/J32),"-",K32/J32) -> - | P32: TOTAL | Q32: CURRENT | R32: =R8+R11+R14+R17+R20+R23+R26+R29 -> 186 | S32: =S8+S11+S14+S17+S20+S23+S26+S29 -> 83 | T32: =R32-S32 -> 103 | U32: =S32/R32 -> 0.44623656 | AE32: DP GENERO ENTERPRISE | AG32: =SUMIF('Summarized Plan'!#REF!,$AE32,'Summarized Plan'!#REF!) -> #REF! | AH32: =SUMIF('Summarized Plan'!#REF!,$AE32,'Summarized Plan'!#REF!) -> #REF! | AI32: =AG32-AH32 -> #REF! | AJ32: =SUMIF('Summarized Plan'!#REF!,$AE32,'Summarized Plan'!#REF!) -> #REF! | AK32: =SUMIF('Summarized Plan'!#REF!,$AE32,'Summarized Plan'!#REF!) -> #REF! | AL32: =AJ32-AK32 -> #REF! | AM32: =AH32/AG32 -> #REF!
Q33: BACKLOG | R33: =R9+R12+R15+R18+R21+R24+R27+R30 -> #REF! | S33: =S9+S12+S15+S18+S21+S24+S27+S30 -> 0 | T33: =R33-S33 -> #REF! | U33: =S33/R33 -> #REF! | AE33: CARRY ALL FOOD ENTERPRISES INC. | AG33: =SUMIF('Summarized Plan'!#REF!,$AE33,'Summarized Plan'!#REF!) -> #REF! | AH33: =SUMIF('Summarized Plan'!#REF!,$AE33,'Summarized Plan'!#REF!) -> #REF! | AI33: =AG33-AH33 -> #REF! | AJ33: =SUMIF('Summarized Plan'!#REF!,$AE33,'Summarized Plan'!#REF!) -> #REF! | AK33: =SUMIF('Summarized Plan'!#REF!,$AE33,'Summarized Plan'!#REF!) -> #REF! | AL33: =AJ33-AK33 -> #REF! | AM33: =AH33/AG33 -> #REF!
I34: MAN-DP | J34: Shipments | L34: Physical Cases | N34: Efficiency | Q34: ADVANCE | R34: =R10+R13+R16+R19+R22+R25+R28+R31 -> #REF! | S34: =S10+S13+S16+S19+S22+S25+S28+S31 -> 0 | T34: =R34-S34 -> #REF! | U34: =S34/R34 -> #REF! | AG34: =SUMIF('Summarized Plan'!#REF!,$AE34,'Summarized Plan'!#REF!) -> #REF! | AH34: =SUMIF('Summarized Plan'!#REF!,$AE34,'Summarized Plan'!#REF!) -> #REF! | AI34: =AG34-AH34 -> #REF! | AJ34: =SUMIF('Summarized Plan'!#REF!,$AE34,'Summarized Plan'!#REF!) -> #REF! | AK34: =SUMIF('Summarized Plan'!#REF!,$AE34,'Summarized Plan'!#REF!) -> #REF! | AL34: =AJ34-AK34 -> #REF! | AM34: =AH34/AG34 -> #REF!
J35: Planned | K35: Dispatched | L35: Planned | M35: Dispatched | P35: Grand Total | R35: =SUM(R32:R34) -> #REF! | S35: =SUM(S32:S34) -> 83 | T35: =R35-S35 -> #REF! | U35: =S35/R35 -> #REF! | AG35: =SUMIF('Summarized Plan'!#REF!,$AE35,'Summarized Plan'!#REF!) -> #REF! | AH35: =SUMIF('Summarized Plan'!#REF!,$AE35,'Summarized Plan'!#REF!) -> #REF! | AI35: =AG35-AH35 -> #REF! | AJ35: =SUMIF('Summarized Plan'!#REF!,$AE35,'Summarized Plan'!#REF!) -> #REF! | AK35: =SUMIF('Summarized Plan'!#REF!,$AE35,'Summarized Plan'!#REF!) -> #REF! | AL35: =AJ35-AK35 -> #REF! | AM35: =AH35/AG35 -> #REF!
I36: Current | J36: =COUNTIFS('Summarized Plan'!$G:$G,'Report Summary'!I34,'Summarized Plan'!$H:$H,'Report Summary'!$C$2) -> 0 | K36: =SUMIFS('Summarized Plan'!$P:$P,'Summarized Plan'!$G:$G,'Report Summary'!I34,'Summarized Plan'!$H:$H,'Report Summary'!$C$2) -> 0 | L36: =SUMIFS('Summarized Plan'!$C:$C,'Summarized Plan'!$G:$G,'Report Summary'!I34,'Summarized Plan'!$H:$H,'Report Summary'!$C$2) -> 0 | M36: =SUMIFS('Summarized Plan'!$Q:$Q,'Summarized Plan'!$G:$G,'Report Summary'!I34,'Summarized Plan'!$H:$H,'Report Summary'!$C$2) -> 0 | N36: =IF(ISERROR(K36/J36),"-",K36/J36) -> - | AG36: =SUMIF('Summarized Plan'!#REF!,$AE36,'Summarized Plan'!#REF!) -> #REF! | AH36: =SUMIF('Summarized Plan'!#REF!,$AE36,'Summarized Plan'!#REF!) -> #REF! | AI36: =AG36-AH36 -> #REF! | AJ36: =SUMIF('Summarized Plan'!#REF!,$AE36,'Summarized Plan'!#REF!) -> #REF! | AK36: =SUMIF('Summarized Plan'!#REF!,$AE36,'Summarized Plan'!#REF!) -> #REF! | AL36: =AJ36-AK36 -> #REF! | AM36: =AH36/AG36 -> #REF!
B37: Total | C37: =SUM(C25:C33) -> 41 | D37: =SUM(D25:D32) -> 17 | E37: =SUM(E25:E32) -> 24 | F37: =+D37/C37 -> 0.41463415 | I37: Backlogs | J37: =SUMIF('Summarized Plan'!$G:$G,'Report Summary'!I34,'Summarized Plan'!$R:$R) -> 0 | K37: =SUMIFS('Summarized Plan'!$P:$P,'Summarized Plan'!$R:$R,"=1",'Summarized Plan'!$G:$G,'Report Summary'!I34) -> 0 | L37: =SUMIFS('Summarized Plan'!$C:$C,'Summarized Plan'!$R:$R,"=1",'Summarized Plan'!$G:$G,'Report Summary'!I34) -> 0 | M37: =SUMIFS('Summarized Plan'!$Q:$Q,'Summarized Plan'!$R:$R,"=1",'Summarized Plan'!$G:$G,'Report Summary'!I34) -> 0 | N37: =IF(ISERROR(K37/J37),"-",K37/J37) -> - | P37: Summary | R37: Volume Loadout | AG37: =SUMIF('Summarized Plan'!#REF!,$AE37,'Summarized Plan'!#REF!) -> #REF! | AH37: =SUMIF('Summarized Plan'!#REF!,$AE37,'Summarized Plan'!#REF!) -> #REF! | AI37: =AG37-AH37 -> #REF! | AJ37: =SUMIF('Summarized Plan'!#REF!,$AE37,'Summarized Plan'!#REF!) -> #REF! | AK37: =SUMIF('Summarized Plan'!#REF!,$AE37,'Summarized Plan'!#REF!) -> #REF! | AL37: =AJ37-AK37 -> #REF! | AM37: =AH37/AG37 -> #REF!
I38: Advanced | J38: =SUMIF('Summarized Plan'!$G:$G,'Report Summary'!I34,'Summarized Plan'!$S:$S) -> 0 | K38: =SUMIFS('Summarized Plan'!$P:$P,'Summarized Plan'!$S:$S,"=1",'Summarized Plan'!$G:$G,'Report Summary'!I34) -> 0 | L38: =SUMIFS('Summarized Plan'!$C:$C,'Summarized Plan'!$S:$S,"=1",'Summarized Plan'!$G:$G,'Report Summary'!I34) -> 0 | M38: =SUMIFS('Summarized Plan'!$Q:$Q,'Summarized Plan'!$S:$S,"=1",'Summarized Plan'!$G:$G,'Report Summary'!I34) -> 0 | N38: =IF(ISERROR(K38/J38),"-",K38/J38) -> - | O38: =R39+R42+R45+R48+R51+R54 -> 44049 | R38: Planned | S38: Dispatched | T38: Variance | U38: Efficiency | AG38: =SUMIF('Summarized Plan'!#REF!,$AE38,'Summarized Plan'!#REF!) -> #REF! | AH38: =SUMIF('Summarized Plan'!#REF!,$AE38,'Summarized Plan'!#REF!) -> #REF! | AI38: =AG38-AH38 -> #REF! | AJ38: =SUMIF('Summarized Plan'!#REF!,$AE38,'Summarized Plan'!#REF!) -> #REF! | AK38: =SUMIF('Summarized Plan'!#REF!,$AE38,'Summarized Plan'!#REF!) -> #REF! | AL38: =AJ38-AK38 -> #REF! | AM38: =AH38/AG38 -> #REF!
B39: Total Attendance | C39: =+C19+C37 -> 150 | D39: =+D19+D37 -> 61 | E39: =+SUM(E37:E38) -> 24 | F39: =+D39/C39 -> 0.40666667 | I39: Total | J39: =SUM(J36:J38) -> 0 | K39: =SUM(K36:K38) -> 0 | L39: =SUM(L36:L38) -> 0 | M39: =SUM(M36:M38) -> 0 | N39: =IF(ISERROR(K39/J39),"-",K39/J39) -> - | O39: =S39+S42+S45+S48+S51+S54 -> 20448 | P39: KA | Q39: CURRENT | R39: =L8 -> 25665 | S39: =M8 -> 14252 | T39: =R39-S39 -> 11413 | U39: =S39/R39 -> 0.55530879 | AG39: =SUMIF('Summarized Plan'!#REF!,$AE39,'Summarized Plan'!#REF!) -> #REF! | AH39: =SUMIF('Summarized Plan'!#REF!,$AE39,'Summarized Plan'!#REF!) -> #REF! | AI39: =AG39-AH39 -> #REF! | AJ39: =SUMIF('Summarized Plan'!#REF!,$AE39,'Summarized Plan'!#REF!) -> #REF! | AK39: =SUMIF('Summarized Plan'!#REF!,$AE39,'Summarized Plan'!#REF!) -> #REF! | AL39: =AJ39-AK39 -> #REF! | AM39: =AH39/AG39 -> #REF!
